[2025-03-20T03:26:58.195+0000] {local_task_job_runner.py:123} INFO - ::group::Pre task execution logs
[2025-03-20T03:26:58.225+0000] {taskinstance.py:2613} INFO - Dependencies all met for dep_context=non-requeueable deps ti=<TaskInstance: dag_etl_docling.trigger_github_workflow manual__2025-03-20T03:26:56.634508+00:00 [queued]>
[2025-03-20T03:26:58.241+0000] {taskinstance.py:2613} INFO - Dependencies all met for dep_context=requeueable deps ti=<TaskInstance: dag_etl_docling.trigger_github_workflow manual__2025-03-20T03:26:56.634508+00:00 [queued]>
[2025-03-20T03:26:58.242+0000] {taskinstance.py:2866} INFO - Starting attempt 1 of 1
[2025-03-20T03:26:58.260+0000] {taskinstance.py:2889} INFO - Executing <Task(HttpOperator): trigger_github_workflow> on 2025-03-20 03:26:56.634508+00:00
[2025-03-20T03:26:58.267+0000] {warnings.py:112} WARNING - /home/***/.local/lib/python3.12/site-packages/***/task/task_runner/standard_task_runner.py:70: DeprecationWarning: This process (pid=597) is multi-threaded, use of fork() may lead to deadlocks in the child.
  pid = os.fork()

[2025-03-20T03:26:58.270+0000] {standard_task_runner.py:72} INFO - Started process 598 to run task
[2025-03-20T03:26:58.270+0000] {standard_task_runner.py:104} INFO - Running: ['***', 'tasks', 'run', 'dag_etl_docling', 'trigger_github_workflow', 'manual__2025-03-20T03:26:56.634508+00:00', '--job-id', '30', '--raw', '--subdir', 'DAGS_FOLDER/dag_etl_docling.py', '--cfg-path', '/tmp/tmpeymagpzk']
[2025-03-20T03:26:58.272+0000] {standard_task_runner.py:105} INFO - Job 30: Subtask trigger_github_workflow
[2025-03-20T03:26:58.322+0000] {task_command.py:467} INFO - Running <TaskInstance: dag_etl_docling.trigger_github_workflow manual__2025-03-20T03:26:56.634508+00:00 [running]> on host ba8d42448b21
[2025-03-20T03:26:58.411+0000] {taskinstance.py:3132} INFO - Exporting env vars: AIRFLOW_CTX_DAG_OWNER='***' AIRFLOW_CTX_DAG_ID='dag_etl_docling' AIRFLOW_CTX_TASK_ID='trigger_github_workflow' AIRFLOW_CTX_EXECUTION_DATE='2025-03-20T03:26:56.634508+00:00' AIRFLOW_CTX_TRY_NUMBER='1' AIRFLOW_CTX_DAG_RUN_ID='manual__2025-03-20T03:26:56.634508+00:00'
[2025-03-20T03:26:58.413+0000] {taskinstance.py:731} INFO - ::endgroup::
[2025-03-20T03:26:58.433+0000] {http.py:175} INFO - Calling HTTP method
[2025-03-20T03:26:58.446+0000] {base.py:84} INFO - Retrieving connection 'github_api'
[2025-03-20T03:26:58.458+0000] {base.py:84} INFO - Retrieving connection 'github_api'
[2025-03-20T03:26:58.667+0000] {http.py:204} ERROR - HTTP error: Forbidden
[2025-03-20T03:26:58.670+0000] {http.py:205} ERROR - {"message":"Must have admin rights to Repository.","documentation_url":"https://docs.github.com/rest/actions/workflows#create-a-workflow-dispatch-event","status":"403"}
[2025-03-20T03:26:58.689+0000] {taskinstance.py:3311} ERROR - Task failed with exception
Traceback (most recent call last):
  File "/home/airflow/.local/lib/python3.12/site-packages/airflow/providers/http/hooks/http.py", line 202, in check_response
    response.raise_for_status()
  File "/home/airflow/.local/lib/python3.12/site-packages/requests/models.py", line 1024, in raise_for_status
    raise HTTPError(http_error_msg, response=self)
requests.exceptions.HTTPError: 403 Client Error: Forbidden for url: https://api.github.com/repos/bigdata-org/AI_Powered_Information_Retrieval/actions/workflows/etl_docling.yaml/dispatches

During handling of the above exception, another exception occurred:

Traceback (most recent call last):
  File "/home/airflow/.local/lib/python3.12/site-packages/airflow/models/taskinstance.py", line 767, in _execute_task
    result = _execute_callable(context=context, **execute_callable_kwargs)
             ^^^^^^^^^^^^^^^^^^^^^^^^^^^^^^^^^^^^^^^^^^^^^^^^^^^^^^^^^^^^^
  File "/home/airflow/.local/lib/python3.12/site-packages/airflow/models/taskinstance.py", line 733, in _execute_callable
    return ExecutionCallableRunner(
           ^^^^^^^^^^^^^^^^^^^^^^^^
  File "/home/airflow/.local/lib/python3.12/site-packages/airflow/utils/operator_helpers.py", line 252, in run
    return self.func(*args, **kwargs)
           ^^^^^^^^^^^^^^^^^^^^^^^^^^
  File "/home/airflow/.local/lib/python3.12/site-packages/airflow/models/baseoperator.py", line 422, in wrapper
    return func(self, *args, **kwargs)
           ^^^^^^^^^^^^^^^^^^^^^^^^^^^
  File "/home/airflow/.local/lib/python3.12/site-packages/airflow/providers/http/operators/http.py", line 172, in execute
    return self.execute_sync(context=context)
           ^^^^^^^^^^^^^^^^^^^^^^^^^^^^^^^^^^
  File "/home/airflow/.local/lib/python3.12/site-packages/airflow/providers/http/operators/http.py", line 186, in execute_sync
    response = self.hook.run(
               ^^^^^^^^^^^^^^
  File "/home/airflow/.local/lib/python3.12/site-packages/airflow/providers/http/hooks/http.py", line 191, in run
    return self.run_and_check(session, prepped_request, extra_options)
           ^^^^^^^^^^^^^^^^^^^^^^^^^^^^^^^^^^^^^^^^^^^^^^^^^^^^^^^^^^^
  File "/home/airflow/.local/lib/python3.12/site-packages/airflow/providers/http/hooks/http.py", line 244, in run_and_check
    self.check_response(response)
  File "/home/airflow/.local/lib/python3.12/site-packages/airflow/providers/http/hooks/http.py", line 206, in check_response
    raise AirflowException(str(response.status_code) + ":" + response.reason)
airflow.exceptions.AirflowException: 403:Forbidden
[2025-03-20T03:26:58.698+0000] {taskinstance.py:1225} INFO - Marking task as FAILED. dag_id=dag_etl_docling, task_id=trigger_github_workflow, run_id=manual__2025-03-20T03:26:56.634508+00:00, execution_date=20250320T032656, start_date=20250320T032658, end_date=20250320T032658
[2025-03-20T03:26:58.715+0000] {taskinstance.py:340} INFO - ::group::Post task execution logs
[2025-03-20T03:26:58.716+0000] {standard_task_runner.py:124} ERROR - Failed to execute job 30 for task trigger_github_workflow (403:Forbidden; 598)
Traceback (most recent call last):
  File "/home/airflow/.local/lib/python3.12/site-packages/airflow/providers/http/hooks/http.py", line 202, in check_response
    response.raise_for_status()
  File "/home/airflow/.local/lib/python3.12/site-packages/requests/models.py", line 1024, in raise_for_status
    raise HTTPError(http_error_msg, response=self)
requests.exceptions.HTTPError: 403 Client Error: Forbidden for url: https://api.github.com/repos/bigdata-org/AI_Powered_Information_Retrieval/actions/workflows/etl_docling.yaml/dispatches

During handling of the above exception, another exception occurred:

Traceback (most recent call last):
  File "/home/airflow/.local/lib/python3.12/site-packages/airflow/task/task_runner/standard_task_runner.py", line 117, in _start_by_fork
    ret = args.func(args, dag=self.dag)
          ^^^^^^^^^^^^^^^^^^^^^^^^^^^^^
  File "/home/airflow/.local/lib/python3.12/site-packages/airflow/cli/cli_config.py", line 49, in command
    return func(*args, **kwargs)
           ^^^^^^^^^^^^^^^^^^^^^
  File "/home/airflow/.local/lib/python3.12/site-packages/airflow/utils/cli.py", line 116, in wrapper
    return f(*args, **kwargs)
           ^^^^^^^^^^^^^^^^^^
  File "/home/airflow/.local/lib/python3.12/site-packages/airflow/cli/commands/task_command.py", line 483, in task_run
    task_return_code = _run_task_by_selected_method(args, _dag, ti)
                       ^^^^^^^^^^^^^^^^^^^^^^^^^^^^^^^^^^^^^^^^^^^^
  File "/home/airflow/.local/lib/python3.12/site-packages/airflow/cli/commands/task_command.py", line 256, in _run_task_by_selected_method
    return _run_raw_task(args, ti)
           ^^^^^^^^^^^^^^^^^^^^^^^
  File "/home/airflow/.local/lib/python3.12/site-packages/airflow/cli/commands/task_command.py", line 341, in _run_raw_task
    return ti._run_raw_task(
           ^^^^^^^^^^^^^^^^^
  File "/home/airflow/.local/lib/python3.12/site-packages/airflow/utils/session.py", line 97, in wrapper
    return func(*args, session=session, **kwargs)
           ^^^^^^^^^^^^^^^^^^^^^^^^^^^^^^^^^^^^^^
  File "/home/airflow/.local/lib/python3.12/site-packages/airflow/models/taskinstance.py", line 3005, in _run_raw_task
    return _run_raw_task(
           ^^^^^^^^^^^^^^
  File "/home/airflow/.local/lib/python3.12/site-packages/airflow/models/taskinstance.py", line 273, in _run_raw_task
    TaskInstance._execute_task_with_callbacks(
  File "/home/airflow/.local/lib/python3.12/site-packages/airflow/models/taskinstance.py", line 3159, in _execute_task_with_callbacks
    result = self._execute_task(context, task_orig)
             ^^^^^^^^^^^^^^^^^^^^^^^^^^^^^^^^^^^^^^
  File "/home/airflow/.local/lib/python3.12/site-packages/airflow/models/taskinstance.py", line 3183, in _execute_task
    return _execute_task(self, context, task_orig)
           ^^^^^^^^^^^^^^^^^^^^^^^^^^^^^^^^^^^^^^^
  File "/home/airflow/.local/lib/python3.12/site-packages/airflow/models/taskinstance.py", line 767, in _execute_task
    result = _execute_callable(context=context, **execute_callable_kwargs)
             ^^^^^^^^^^^^^^^^^^^^^^^^^^^^^^^^^^^^^^^^^^^^^^^^^^^^^^^^^^^^^
  File "/home/airflow/.local/lib/python3.12/site-packages/airflow/models/taskinstance.py", line 733, in _execute_callable
    return ExecutionCallableRunner(
           ^^^^^^^^^^^^^^^^^^^^^^^^
  File "/home/airflow/.local/lib/python3.12/site-packages/airflow/utils/operator_helpers.py", line 252, in run
    return self.func(*args, **kwargs)
           ^^^^^^^^^^^^^^^^^^^^^^^^^^
  File "/home/airflow/.local/lib/python3.12/site-packages/airflow/models/baseoperator.py", line 422, in wrapper
    return func(self, *args, **kwargs)
           ^^^^^^^^^^^^^^^^^^^^^^^^^^^
  File "/home/airflow/.local/lib/python3.12/site-packages/airflow/providers/http/operators/http.py", line 172, in execute
    return self.execute_sync(context=context)
           ^^^^^^^^^^^^^^^^^^^^^^^^^^^^^^^^^^
  File "/home/airflow/.local/lib/python3.12/site-packages/airflow/providers/http/operators/http.py", line 186, in execute_sync
    response = self.hook.run(
               ^^^^^^^^^^^^^^
  File "/home/airflow/.local/lib/python3.12/site-packages/airflow/providers/http/hooks/http.py", line 191, in run
    return self.run_and_check(session, prepped_request, extra_options)
           ^^^^^^^^^^^^^^^^^^^^^^^^^^^^^^^^^^^^^^^^^^^^^^^^^^^^^^^^^^^
  File "/home/airflow/.local/lib/python3.12/site-packages/airflow/providers/http/hooks/http.py", line 244, in run_and_check
    self.check_response(response)
  File "/home/airflow/.local/lib/python3.12/site-packages/airflow/providers/http/hooks/http.py", line 206, in check_response
    raise AirflowException(str(response.status_code) + ":" + response.reason)
airflow.exceptions.AirflowException: 403:Forbidden
[2025-03-20T03:26:58.728+0000] {local_task_job_runner.py:266} INFO - Task exited with return code 1
[2025-03-20T03:26:58.747+0000] {taskinstance.py:3895} INFO - 0 downstream tasks scheduled from follow-on schedule check
[2025-03-20T03:26:58.750+0000] {local_task_job_runner.py:245} INFO - ::endgroup::
